<robot name="nome_robo"><link name="link_principal"><inertial><mass value="5" /><inertia ixx="1.0" ixy="0.0" ixz="0.0" iyy="1.0" iyz="0.0" izz="1.0" /></inertial><collision><origin xyz="0 0 0" /><geometry><box size="1.5 1.4 0.5" /></geometry></collision><visual><origin xyz="0 0 0" /><geometry><box size="1.5 1.4 0.5" /></geometry></visual></link><link name="link1"><inertial><mass value="5" /><inertia ixx="1.0" ixy="0.0" ixz="0.0" iyy="1.0" iyz="0.0" izz="1.0" /></inertial><collision><origin xyz="0 0 0" /><geometry><sphere radius="1.1" /></geometry></collision><visual><origin xyz="0 0 0" /><geometry><sphere radius="1.1" /></geometry></visual></link><joint name="joint1" type="fixed"><origin xyz="2.0 0 0" /><parent link="link_principal" /><child link="link1" /></joint><link name="link2"><inertial><mass value="5" /><inertia ixx="1.0" ixy="0.0" ixz="0.0" iyy="1.0" iyz="0.0" izz="1.0" /></inertial><collision><origin xyz="0 0 0" /><geometry><sphere radius="1.3" /></geometry></collision><visual><origin xyz="0 0 0" /><geometry><sphere radius="1.3" /></geometry></visual></link><joint name="joint2" type="continuous"><origin xyz="1.5 0 0" /><parent link="link1" /><child link="link2" /></joint><link name="link3"><inertial><mass value="5" /><inertia ixx="1.0" ixy="0.0" ixz="0.0" iyy="1.0" iyz="0.0" izz="1.0" /></inertial><collision><origin xyz="0 0 0" /><geometry><cylinder length="0.5" radius="1.0" /></geometry></collision><visual><origin xyz="0 0 0" /><geometry><cylinder length="0.5" radius="1.0" /></geometry></visual></link><joint name="joint3" type="continuous"><origin xyz="2.0 0 0" /><parent link="link2" /><child link="link3" /></joint></robot>