<robot name="nome_robo"><link name="link_principal"><inertial><mass value="5" /><inertia ixx="1.0" ixy="0.0" ixz="0.0" iyy="1.0" iyz="0.0" izz="1.0" /></inertial><collision><origin xyz="0 0 1" /><geometry><sphere radius="1.1" /></geometry></collision><visual><origin xyz="0 0 1" /><geometry><sphere radius="1.1" /></geometry></visual></link><link name="link1"><inertial><mass value="5" /><inertia ixx="1.0" ixy="0.0" ixz="0.0" iyy="1.0" iyz="0.0" izz="1.0" /></inertial><collision><origin xyz="0 0 1" /><geometry><box size="0.7 0.3 0.7" /></geometry></collision><visual><origin xyz="0 0 1" /><geometry><box size="0.7 0.3 0.7" /></geometry></visual></link><joint name="joint1" type="continuous"><origin xyz="0 1.4 1" /><parent link="link_principal" /><child link="link1" /></joint></robot>